[2024-09-23T18:07:02.452+0000] {taskinstance.py:1165} INFO - Dependencies all met for <TaskInstance: user_processing.process_user manual__2024-09-23T18:06:57.815384+00:00 [queued]>
[2024-09-23T18:07:02.470+0000] {taskinstance.py:1165} INFO - Dependencies all met for <TaskInstance: user_processing.process_user manual__2024-09-23T18:06:57.815384+00:00 [queued]>
[2024-09-23T18:07:02.472+0000] {taskinstance.py:1362} INFO - 
--------------------------------------------------------------------------------
[2024-09-23T18:07:02.473+0000] {taskinstance.py:1363} INFO - Starting attempt 1 of 1
[2024-09-23T18:07:02.474+0000] {taskinstance.py:1364} INFO - 
--------------------------------------------------------------------------------
[2024-09-23T18:07:02.495+0000] {taskinstance.py:1383} INFO - Executing <Task(PythonOperator): process_user> on 2024-09-23 18:06:57.815384+00:00
[2024-09-23T18:07:02.503+0000] {standard_task_runner.py:55} INFO - Started process 14628 to run task
[2024-09-23T18:07:02.510+0000] {standard_task_runner.py:82} INFO - Running: ['***', 'tasks', 'run', 'user_processing', 'process_user', 'manual__2024-09-23T18:06:57.815384+00:00', '--job-id', '39', '--raw', '--subdir', 'DAGS_FOLDER/user_processing.py', '--cfg-path', '/tmp/tmp19ys0rtm']
[2024-09-23T18:07:02.514+0000] {standard_task_runner.py:83} INFO - Job 39: Subtask process_user
[2024-09-23T18:07:02.627+0000] {task_command.py:376} INFO - Running <TaskInstance: user_processing.process_user manual__2024-09-23T18:06:57.815384+00:00 [running]> on host 3faff16bae04
[2024-09-23T18:07:02.734+0000] {taskinstance.py:1592} INFO - Exporting the following env vars:
AIRFLOW_CTX_DAG_OWNER=***
AIRFLOW_CTX_DAG_ID=user_processing
AIRFLOW_CTX_TASK_ID=process_user
AIRFLOW_CTX_EXECUTION_DATE=2024-09-23T18:06:57.815384+00:00
AIRFLOW_CTX_TRY_NUMBER=1
AIRFLOW_CTX_DAG_RUN_ID=manual__2024-09-23T18:06:57.815384+00:00
[2024-09-23T18:07:02.774+0000] {taskinstance.py:1851} ERROR - Task failed with exception
Traceback (most recent call last):
  File "/home/airflow/.local/lib/python3.7/site-packages/airflow/operators/python.py", line 175, in execute
    return_value = self.execute_callable()
  File "/home/airflow/.local/lib/python3.7/site-packages/airflow/operators/python.py", line 193, in execute_callable
    return self.python_callable(*self.op_args, **self.op_kwargs)
  File "/opt/airflow/dags/user_processing.py", line 23, in _process_user
    processed_user.to_csv('tmp/processed_user.csv', index = None, header = False)
  File "/home/airflow/.local/lib/python3.7/site-packages/pandas/core/generic.py", line 3482, in to_csv
    storage_options=storage_options,
  File "/home/airflow/.local/lib/python3.7/site-packages/pandas/io/formats/format.py", line 1105, in to_csv
    csv_formatter.save()
  File "/home/airflow/.local/lib/python3.7/site-packages/pandas/io/formats/csvs.py", line 243, in save
    storage_options=self.storage_options,
  File "/home/airflow/.local/lib/python3.7/site-packages/pandas/io/common.py", line 707, in get_handle
    newline="",
FileNotFoundError: [Errno 2] No such file or directory: 'tmp/processed_user.csv'
[2024-09-23T18:07:02.792+0000] {taskinstance.py:1406} INFO - Marking task as FAILED. dag_id=user_processing, task_id=process_user, execution_date=20240923T180657, start_date=20240923T180702, end_date=20240923T180702
[2024-09-23T18:07:02.811+0000] {standard_task_runner.py:105} ERROR - Failed to execute job 39 for task process_user ([Errno 2] No such file or directory: 'tmp/processed_user.csv'; 14628)
[2024-09-23T18:07:02.843+0000] {local_task_job.py:164} INFO - Task exited with return code 1
[2024-09-23T18:07:02.871+0000] {local_task_job.py:273} INFO - 0 downstream tasks scheduled from follow-on schedule check
