[2024-09-23T18:02:40.722+0000] {taskinstance.py:1165} INFO - Dependencies all met for <TaskInstance: user_processing.process_user manual__2024-09-23T18:02:37.435668+00:00 [queued]>
[2024-09-23T18:02:40.740+0000] {taskinstance.py:1165} INFO - Dependencies all met for <TaskInstance: user_processing.process_user manual__2024-09-23T18:02:37.435668+00:00 [queued]>
[2024-09-23T18:02:40.741+0000] {taskinstance.py:1362} INFO - 
--------------------------------------------------------------------------------
[2024-09-23T18:02:40.743+0000] {taskinstance.py:1363} INFO - Starting attempt 1 of 1
[2024-09-23T18:02:40.744+0000] {taskinstance.py:1364} INFO - 
--------------------------------------------------------------------------------
[2024-09-23T18:02:40.778+0000] {taskinstance.py:1383} INFO - Executing <Task(PythonOperator): process_user> on 2024-09-23 18:02:37.435668+00:00
[2024-09-23T18:02:40.793+0000] {standard_task_runner.py:55} INFO - Started process 14386 to run task
[2024-09-23T18:02:40.809+0000] {standard_task_runner.py:82} INFO - Running: ['***', 'tasks', 'run', 'user_processing', 'process_user', 'manual__2024-09-23T18:02:37.435668+00:00', '--job-id', '26', '--raw', '--subdir', 'DAGS_FOLDER/user_processing.py', '--cfg-path', '/tmp/tmp43e5rjtj']
[2024-09-23T18:02:40.815+0000] {standard_task_runner.py:83} INFO - Job 26: Subtask process_user
[2024-09-23T18:02:41.001+0000] {task_command.py:376} INFO - Running <TaskInstance: user_processing.process_user manual__2024-09-23T18:02:37.435668+00:00 [running]> on host 3faff16bae04
[2024-09-23T18:02:41.182+0000] {taskinstance.py:1592} INFO - Exporting the following env vars:
AIRFLOW_CTX_DAG_OWNER=***
AIRFLOW_CTX_DAG_ID=user_processing
AIRFLOW_CTX_TASK_ID=process_user
AIRFLOW_CTX_EXECUTION_DATE=2024-09-23T18:02:37.435668+00:00
AIRFLOW_CTX_TRY_NUMBER=1
AIRFLOW_CTX_DAG_RUN_ID=manual__2024-09-23T18:02:37.435668+00:00
[2024-09-23T18:02:41.186+0000] {taskinstance.py:1851} ERROR - Task failed with exception
Traceback (most recent call last):
  File "/home/airflow/.local/lib/python3.7/site-packages/airflow/operators/python.py", line 175, in execute
    return_value = self.execute_callable()
  File "/home/airflow/.local/lib/python3.7/site-packages/airflow/operators/python.py", line 193, in execute_callable
    return self.python_callable(*self.op_args, **self.op_kwargs)
  File "/opt/airflow/dags/user_processing.py", line 12, in _process_user
    user = ti.xcom_pull(task_id = 'extract_user')
  File "/home/airflow/.local/lib/python3.7/site-packages/airflow/utils/session.py", line 75, in wrapper
    return func(*args, session=session, **kwargs)
TypeError: xcom_pull() got an unexpected keyword argument 'task_id'
[2024-09-23T18:02:41.226+0000] {taskinstance.py:1406} INFO - Marking task as FAILED. dag_id=user_processing, task_id=process_user, execution_date=20240923T180237, start_date=20240923T180240, end_date=20240923T180241
[2024-09-23T18:02:41.253+0000] {standard_task_runner.py:105} ERROR - Failed to execute job 26 for task process_user (xcom_pull() got an unexpected keyword argument 'task_id'; 14386)
[2024-09-23T18:02:41.301+0000] {local_task_job.py:164} INFO - Task exited with return code 1
[2024-09-23T18:02:41.363+0000] {local_task_job.py:273} INFO - 0 downstream tasks scheduled from follow-on schedule check
