[2024-09-23T18:04:45.872+0000] {taskinstance.py:1165} INFO - Dependencies all met for <TaskInstance: user_processing.process_user manual__2024-09-23T18:04:41.767643+00:00 [queued]>
[2024-09-23T18:04:45.890+0000] {taskinstance.py:1165} INFO - Dependencies all met for <TaskInstance: user_processing.process_user manual__2024-09-23T18:04:41.767643+00:00 [queued]>
[2024-09-23T18:04:45.891+0000] {taskinstance.py:1362} INFO - 
--------------------------------------------------------------------------------
[2024-09-23T18:04:45.892+0000] {taskinstance.py:1363} INFO - Starting attempt 1 of 1
[2024-09-23T18:04:45.893+0000] {taskinstance.py:1364} INFO - 
--------------------------------------------------------------------------------
[2024-09-23T18:04:45.919+0000] {taskinstance.py:1383} INFO - Executing <Task(PythonOperator): process_user> on 2024-09-23 18:04:41.767643+00:00
[2024-09-23T18:04:45.928+0000] {standard_task_runner.py:55} INFO - Started process 14495 to run task
[2024-09-23T18:04:45.934+0000] {standard_task_runner.py:82} INFO - Running: ['***', 'tasks', 'run', 'user_processing', 'process_user', 'manual__2024-09-23T18:04:41.767643+00:00', '--job-id', '31', '--raw', '--subdir', 'DAGS_FOLDER/user_processing.py', '--cfg-path', '/tmp/tmp29ia15v2']
[2024-09-23T18:04:45.938+0000] {standard_task_runner.py:83} INFO - Job 31: Subtask process_user
[2024-09-23T18:04:46.049+0000] {task_command.py:376} INFO - Running <TaskInstance: user_processing.process_user manual__2024-09-23T18:04:41.767643+00:00 [running]> on host 3faff16bae04
[2024-09-23T18:04:46.159+0000] {taskinstance.py:1592} INFO - Exporting the following env vars:
AIRFLOW_CTX_DAG_OWNER=***
AIRFLOW_CTX_DAG_ID=user_processing
AIRFLOW_CTX_TASK_ID=process_user
AIRFLOW_CTX_EXECUTION_DATE=2024-09-23T18:04:41.767643+00:00
AIRFLOW_CTX_TRY_NUMBER=1
AIRFLOW_CTX_DAG_RUN_ID=manual__2024-09-23T18:04:41.767643+00:00
[2024-09-23T18:04:46.162+0000] {taskinstance.py:1851} ERROR - Task failed with exception
Traceback (most recent call last):
  File "/home/airflow/.local/lib/python3.7/site-packages/airflow/operators/python.py", line 175, in execute
    return_value = self.execute_callable()
  File "/home/airflow/.local/lib/python3.7/site-packages/airflow/operators/python.py", line 193, in execute_callable
    return self.python_callable(*self.op_args, **self.op_kwargs)
  File "/opt/airflow/dags/user_processing.py", line 12, in _process_user
    user = ti.xcom_pull(task_id = 'extract_user')
  File "/home/airflow/.local/lib/python3.7/site-packages/airflow/utils/session.py", line 75, in wrapper
    return func(*args, session=session, **kwargs)
TypeError: xcom_pull() got an unexpected keyword argument 'task_id'
[2024-09-23T18:04:46.182+0000] {taskinstance.py:1406} INFO - Marking task as FAILED. dag_id=user_processing, task_id=process_user, execution_date=20240923T180441, start_date=20240923T180445, end_date=20240923T180446
[2024-09-23T18:04:46.202+0000] {standard_task_runner.py:105} ERROR - Failed to execute job 31 for task process_user (xcom_pull() got an unexpected keyword argument 'task_id'; 14495)
[2024-09-23T18:04:46.227+0000] {local_task_job.py:164} INFO - Task exited with return code 1
[2024-09-23T18:04:46.256+0000] {local_task_job.py:273} INFO - 0 downstream tasks scheduled from follow-on schedule check
